<?xml version="1.0" encoding="utf-8"?>
<!-- This URDF was automatically created by SolidWorks to URDF Exporter! Originally created by Stephen Brawner (brawner@gmail.com) 
     Commit Version: 1.6.0-4-g7f85cfe  Build Version: 1.6.7995.38578
     For more information, please see http://wiki.ros.org/sw_urdf_exporter -->
<robot name="russ">
  <link name="table_base_link">
    <inertial>
      <origin xyz="8.38237408928855E-08 0.206103274520293 0.463276051921847" rpy="0 0 0" />
      <mass value="309.143354179708" />
      <inertia ixx="20.3943452014122" ixy="6.26686219975331E-06" ixz="5.01704867174039E-06" iyy="26.0520889270766" iyz="-2.88934452540239" izz="22.1482784260504" />
    </inertial>
    <visual>
      <origin xyz="0 0 0" rpy="0 0 0" />
      <geometry>
        <mesh filename="package://russ_description/meshes/base_link.STL" />
      </geometry>
      <material name="">
        <color rgba="0.898039215686275 0.917647058823529 0.929411764705882 1" />
      </material>
    </visual>
    <collision>
      <origin xyz="0 0 0" rpy="0 0 0" />
      <geometry>
        <mesh filename="package://russ_description/meshes/base_link.STL" />
      </geometry>
    </collision>
  </link>
  <link name="world"/>
  <joint name="world_joint" type="fixed">
    <parent link="world"/>
    <child link="table_base_link"/>
    <origin rpy="0.0 0.0 0.0" xyz="0.0 0.0 0.0"/>
  </joint>
  <link name="bed_link">
    <inertial>
      <origin xyz="-1.3323E-15 -2.2204E-16 -0.086988" rpy="0 0 0" />
      <mass value="429.6" />
      <inertia ixx="25.702" ixy="-0.00012352" ixz="-1.3711E-13" iyy="178.76" iyz="-3.3916E-14" izz="193.28" />
    </inertial>
    <visual>
      <origin xyz="0 0 0" rpy="0 0 0" />
      <geometry>
        <mesh filename="package://russ_description/meshes/bed_link.STL" />
      </geometry>
      <material name="">
        <color rgba="0.89804 0.91765 0.92941 1" />
      </material>
    </visual>
    <collision>
      <origin xyz="0 0 0" rpy="0 0 0" />
      <geometry>
        <mesh filename="package://russ_description/meshes/bed_link.STL" />
      </geometry>
    </collision>
  </link>
  <joint name="bed_joint" type="fixed">
    <origin xyz="-0.4 0.87 0.6" rpy="0 0 0" />
    <parent link="table_base_link" />
    <child link="bed_link" />
    <axis xyz="0 0 0" />
  </joint>
  <link name="camera_holder_link">
    <inertial>
      <origin xyz="0.44034 -4.5935E-15 0.6983" rpy="0 0 0" />
      <mass value="10.767" />
      <inertia ixx="2.1559" ixy="-4.985E-09" ixz="-1.2306" iyy="2.8448" iyz="2.8781E-09" izz="0.76073" />
    </inertial>
    <visual>
      <origin xyz="0 0 0" rpy="0 0 0" />
      <geometry>
        <mesh filename="package://russ_description/meshes/camera_holder_link.STL" />
      </geometry>
      <material name="">
        <color rgba="0.89804 0.91765 0.92941 1" />
      </material>
    </visual>
    <collision>
      <origin xyz="0 0 0" rpy="0 0 0" />
      <geometry>
        <mesh filename="package://russ_description/meshes/camera_holder_link.STL" />
      </geometry>
    </collision>
  </link>
  <joint name="camera_holder_joint" type="fixed">
    <origin xyz="0 1.3832 1.4643" rpy="3.1416 0.5236 1.5708" />
    <parent link="table_base_link" />
    <child link="camera_holder_link" />
    <axis xyz="0 0 0" />
  </joint>
  <link name="kinect_link">
    <inertial>
      <origin xyz="0.0070113 0.0024111 -0.00023078" rpy="0 1.5708 0" />
      <mass value="0.64645" />
      <inertia ixx="0.0029627" ixy="3.4581E-08" ixz="-1.4774E-07" iyy="0.00026363" iyz="-2.566E-06" izz="0.0028425" />
    </inertial>
    <visual>
      <origin xyz="0 0 0" rpy="0 1.5708 0" />
      <geometry>
        <mesh filename="package://russ_description/meshes/camera_link.STL" />
      </geometry>
      <material name="">
        <color rgba="0.79216 0.81961 0.93333 1" />
      </material>
    </visual>
    <collision>
      <origin xyz="0 0 0" rpy="0 1.5708 0" />
      <geometry>
        <mesh filename="package://russ_description/meshes/camera_link.STL" />
      </geometry>
    </collision>
  </link>
  <joint name="kinect_joint" type="fixed">
    <origin xyz="-0.05355 -0.0021296 0.016187" rpy="0 -1.5708 0" />
    <parent link="camera_holder_link" />
    <child link="kinect_link" />
    <axis xyz="0 0 0" />
  </joint>
  <link name="base_link">
    <inertial>
      <origin xyz="-1.4294E-05 -0.038283 0.056106" rpy="0 0 0" />
      <mass value="4" />
      <inertia ixx="0.0016928" ixy="-1.142E-07" ixz="-5.6886E-07" iyy="0.0012525" iyz="-2.3851E-05" izz="0.0020811" />
    </inertial>
    <visual>
      <origin xyz="0 0 0" rpy="0 0 0" />
      <geometry>
        <mesh filename="package://russ_description/meshes/arm_base_link.STL" />
      </geometry>
      <material name="">
        <color rgba="1 1 1 1" />
      </material>
    </visual>
    <collision>
      <origin xyz="0 0 0" rpy="0 0 0" />
      <geometry>
        <mesh filename="package://russ_description/meshes/arm_base_link.STL" />
      </geometry>
    </collision>
  </link>
  <joint name="base_joint" type="fixed">
    <origin xyz="0 0.37 0.7002" rpy="0 0 0" />
    <parent link="table_base_link" />
    <child link="base_link" />
    <axis xyz="0 0 0" />
  </joint>
  <link name="shoulder_link">
    <inertial>
      <origin xyz="-3.5623E-06 0.010909 0.00011678" rpy="0 0 0" />
      <mass value="3.7" />
      <inertia ixx="0.0039246" ixy="-4.6692E-08" ixz="4.0132E-08" iyy="0.0034476" iyz="-9.4718E-05" izz="0.0033425" />
    </inertial>
    <visual>
      <origin xyz="0 0 0" rpy="0 0 0" />
      <geometry>
        <mesh filename="package://russ_description/meshes/shoulder_link.STL" />
      </geometry>
      <material name="">
        <color rgba="1 1 1 1" />
      </material>
    </visual>
    <collision>
      <origin xyz="0 0 0" rpy="0 0 0" />
      <geometry>
        <mesh filename="package://russ_description/meshes/shoulder_link.STL" />
      </geometry>
    </collision>
  </link>
  <joint name="shoulder_joint" type="revolute">
    <origin xyz="0 0 0.1623" rpy="0 0 0" />
    <parent link="base_link" />
    <child link="shoulder_link" />
    <axis xyz="0 0 1" />
    <limit lower="-3.14159265" upper="3.14159265" effort="150" velocity="3.15" />
    <dynamics damping="0" friction="0" />
  </joint>
  <link name="upperarm_link">
    <inertial>
      <origin xyz="-6.0796E-06 0.00010671 0.2125" rpy="0 0 0" />
      <mass value="8.393" />
      <inertia ixx="0.14144" ixy="1.9187E-07" ixz="1.2829E-06" iyy="0.14028" iyz="-4.607E-07" izz="0.007421" />
    </inertial>
    <visual>
      <origin xyz="0 0 0" rpy="0 0 0" />
      <geometry>
        <mesh filename="package://russ_description/meshes/upperarm_link.STL" />
      </geometry>
      <material name="">
        <color rgba="1 1 1 1" />
      </material>
    </visual>
    <collision>
      <origin xyz="0 0 0" rpy="0 0 0" />
      <geometry>
        <mesh filename="package://russ_description/meshes/upperarm_link.STL" />
      </geometry>
    </collision>
  </link>
  <joint name="upperarm_joint" type="revolute">
    <origin xyz="0 0.1378 0" rpy="0 0 0" />
    <parent link="shoulder_link" />
    <child link="upperarm_link" />
    <axis xyz="0 1 0" />
    <limit lower="-3.14159265" upper="3.14159265" effort="150" velocity="3.15" />
    <dynamics damping="0" friction="0" />
  </joint>
  <link name="forearm_link">
    <inertial>
      <origin xyz="-2.2953E-05 0.010608 0.14792" rpy="0 0 0" />
      <mass value="2.275" />
      <inertia ixx="0.053639" ixy="1.0574E-05" ixz="-9.1443E-06" iyy="0.053127" iyz="0.0035172" izz="0.0026829" />
    </inertial>
    <visual>
      <origin xyz="0 0 0" rpy="0 0 0" />
      <geometry>
        <mesh filename="package://russ_description/meshes/forearm_link.STL" />
      </geometry>
      <material name="">
        <color rgba="1 1 1 1" />
      </material>
    </visual>
    <collision>
      <origin xyz="0 0 0" rpy="0 0 0" />
      <geometry>
        <mesh filename="package://russ_description/meshes/forearm_link.STL" />
      </geometry>
    </collision>
  </link>
  <joint name="forearm_joint" type="revolute">
    <origin xyz="0 -0.1312 0.425" rpy="0 0 0" />
    <parent link="upperarm_link" />
    <child link="forearm_link" />
    <axis xyz="0 1 0" />
    <limit lower="-3.14159265" upper="3.14159265" effort="150" velocity="3.15" />
    <dynamics damping="0" friction="0" />
  </joint>
  <link name="wrist1_link">
    <inertial>
      <origin xyz="-8.348E-06 0.10839 -0.002548" rpy="0 0 0" />
      <mass value="1.219" />
      <inertia ixx="0.0010919" ixy="2.8181E-07" ixz="-1.116E-07" iyy="0.00068611" iyz="2.5893E-05" izz="0.00088473" />
    </inertial>
    <visual>
      <origin xyz="0 0 0" rpy="0 0 0" />
      <geometry>
        <mesh filename="package://russ_description/meshes/wrist1_link.STL" />
      </geometry>
      <material name="">
        <color rgba="1 1 1 1" />
      </material>
    </visual>
    <collision>
      <origin xyz="0 0 0" rpy="0 0 0" />
      <geometry>
        <mesh filename="package://russ_description/meshes/wrist1_link.STL" />
      </geometry>
    </collision>
  </link>
  <joint name="wrist1_joint" type="revolute">
    <origin xyz="0 0 0.39225" rpy="0 0 0" />
    <parent link="forearm_link" />
    <child link="wrist1_link" />
    <axis xyz="0 1 0" />
    <limit lower="-3.14159265" upper="3.14159265" effort="28" velocity="3.2" />
    <dynamics damping="0" friction="0" />
  </joint>
  <link name="wrist2_link">
    <inertial>
      <origin xyz="8.9592E-06 -0.00311 0.092148" rpy="0 0 0" />
      <mass value="1.219" />
      <inertia ixx="0.00069812" ixy="1.1121E-07" ixz="-2.3236E-07" iyy="0.00049175" iyz="7.5563E-06" izz="0.00060119" />
    </inertial>
    <visual>
      <origin xyz="0 0 0" rpy="0 0 0" />
      <geometry>
        <mesh filename="package://russ_description/meshes/wrist2_link.STL" />
      </geometry>
      <material name="">
        <color rgba="1 1 1 1" />
      </material>
    </visual>
    <collision>
      <origin xyz="0 0 0" rpy="0 0 0" />
      <geometry>
        <mesh filename="package://russ_description/meshes/wrist2_link.STL" />
      </geometry>
    </collision>
  </link>
  <joint name="wrist2_joint" type="revolute">
    <origin xyz="0 0.1267 0" rpy="0 0 0" />
    <parent link="wrist1_link" />
    <child link="wrist2_link" />
    <axis xyz="0 0 1" />
    <limit lower="-3.14159265" upper="3.14159265" effort="28" velocity="3.2" />
    <dynamics damping="0" friction="0" />
  </joint>
  <link name="wrist3_link">
    <inertial>
      <origin xyz="-7.0404E-10 0.075061 -1.5938E-05" rpy="0 0 0" />
      <mass value="0.1879" />
      <inertia ixx="0.00012784" ixy="8.6493E-12" ixz="-2.7362E-09" iyy="0.00016475" iyz="-1.6101E-07" izz="0.00012855" />
    </inertial>
    <visual>
      <origin xyz="0 0 0" rpy="0 0 0" />
      <geometry>
        <mesh filename="package://russ_description/meshes/wrist3_link.STL" />
      </geometry>
      <material name="">
        <color rgba="1 1 1 1" />
      </material>
    </visual>
    <collision>
      <origin xyz="0 0 0" rpy="0 0 0" />
      <geometry>
        <mesh filename="package://russ_description/meshes/wrist3_link.STL" />
      </geometry>
    </collision>
  </link>
  <joint name="wrist3_joint" type="revolute">
    <origin xyz="0 0 0.0997" rpy="0 0 0" />
    <parent link="wrist2_link" />
    <child link="wrist3_link" />
    <axis xyz="0 1 0" />
    <limit lower="-3.1416" upper="3.1416" effort="28" velocity="3.2" />
    <dynamics damping="0" friction="0" />
  </joint>
  <link name="probe_link">
    <inertial>
      <origin xyz="-8.8458E-05 -0.067338 8.8555E-05" rpy="0 0 0" />
      <mass value="0.31983" />
      <inertia ixx="0.00065295" ixy="1.2816E-06" ixz="-1.8903E-05" iyy="0.00013543" iyz="-1.2806E-06" izz="0.00065295" />
    </inertial>
    <visual>
      <origin xyz="0 0 0" rpy="0 0 0" />
      <geometry>
        <mesh filename="package://russ_description/meshes/probe_link.STL" />
      </geometry>
      <material name="">
        <color rgba="0.79216 0.81961 0.93333 1" />
      </material>
    </visual>
    <collision>
      <origin xyz="0 0 0" rpy="0 0 0" />
      <geometry>
        <mesh filename="package://russ_description/meshes/probe_link.STL" />
      </geometry>
    </collision>
  </link>
  <joint name="probe_joint" type="fixed">
    <origin xyz="0 0.268599999411803 0" rpy="0 0 0" />
    <parent link="wrist3_link" />
    <child link="probe_link" />
    <axis xyz="0 0 0" />
  </joint>

  <ros2_control name="GazeboSystem" type="system">
    <hardware>
      <plugin>gazebo_ros2_control/GazeboSystem</plugin>
    </hardware>
    <joint name="shoulder_joint">
      <command_interface name="position">
        <param name="min">-1</param>
        <param name="max">1</param>
      </command_interface>
      <state_interface name="position">
        <param name="initial_value">0.0</param>
      </state_interface>
      <state_interface name="velocity"/>
    </joint>
    <joint name="upperarm_joint">
      <command_interface name="position">
        <param name="min">-1</param>
        <param name="max">1</param>
      </command_interface>
      <state_interface name="position">
        <param name="initial_value">0.0</param>
      </state_interface>
      <state_interface name="velocity"/>
    </joint>
    <joint name="forearm_joint">
      <command_interface name="position">
        <param name="min">-1</param>
        <param name="max">1</param>
      </command_interface>
      <state_interface name="position">
        <param name="initial_value">0.0</param>
      </state_interface>
      <state_interface name="velocity"/>
    </joint>
    <joint name="wrist1_joint">
      <command_interface name="position">
        <param name="min">-1</param>
        <param name="max">1</param>
      </command_interface>
      <state_interface name="position">
        <param name="initial_value">0.0</param>
      </state_interface>
      <state_interface name="velocity"/>
    </joint>
    <joint name="wrist2_joint">
      <command_interface name="position">
        <param name="min">-1</param>
        <param name="max">1</param>
      </command_interface>
      <state_interface name="position">
        <param name="initial_value">0.0</param>
      </state_interface>
      <state_interface name="velocity"/>
    </joint>
    <joint name="wrist3_joint">
      <command_interface name="position">
        <param name="min">-1</param>
        <param name="max">1</param>
      </command_interface>
      <state_interface name="position">
        <param name="initial_value">0.0</param>
      </state_interface>
      <state_interface name="velocity"/>
    </joint>
  </ros2_control>

  <gazebo reference="kinect_link">
    <sensor type="depth" name="camera">
      <!-- Set always_on only sensor, not on plugin -->
      <always_on>1</always_on>

      <!-- Set update_rate only sensor, not on plugin -->
      <update_rate>20.0</update_rate>

      <camera name="kinect">
        <horizontal_fov>1.05</horizontal_fov>
        <image>
          <format>R8G8B8</format>
          <width>640</width>
          <height>480</height>
        </image>
        <clip>
          <near>0.05</near>
          <far>3.0</far>
        </clip>
        <distortion>
          <k1>0.0</k1>
          <k2>0.0</k2>
          <k3>0.0</k3>
          <p1>0.0</p1>
          <p2>0.0</p2>
          <center>0.0 0.0</center>
        </distortion>
      </camera>
      <plugin name="kinect_camera_controller" filename="libgazebo_ros_camera.so">
        <!-- Change namespace, camera name and topics so -
                 * Raw images are published to: /custom_ns/custom_camera/custom_image
                 * Depth images are published to: /custom_ns/custom_camera/custom_image_depth
                 * Raw image camera info is published to: /custom_ns/custom_camera/custom_info_raw
                 * Depth image camera info is published to: /custom_ns/custom_camera/custom_info_depth
                 * Point cloud is published to: /custom_ns/custom_camera/custom_points
            -->
        <ros>
          <namespace>custom_ns</namespace>
          <remapping>custom_camera/image_raw:=custom_camera/custom_image</remapping>
          <remapping>custom_camera/image_depth:=custom_camera/custom_image_depth</remapping>
          <remapping>custom_camera/camera_info:=custom_camera/custom_info_raw</remapping>
          <remapping>custom_camera/camera_info_depth:=custom_camera/custom_info_depth</remapping>
          <remapping>custom_camera/points:=custom_camera/custom_points</remapping>
        </ros>

        <!-- Set camera name. If empty, defaults to sensor name (i.e. "sensor_name") -->
        <camera_name>custom_camera</camera_name>

        <!-- Set TF frame name. If empty, defaults to link name (i.e. "link_name") -->
        <frame_name>kinect_link</frame_name>
        <!-- <frame_name>base_link</frame_name> -->
        <!-- <frame_name>world</frame_name> -->

        <hack_baseline>0.07</hack_baseline>

        <!-- No need to repeat distortion parameters or to set autoDistortion -->

        <min_depth>0.001</min_depth>
        <max_depth>300.0</max_depth>
      </plugin>
    </sensor>
  </gazebo>

  <gazebo>
    <plugin filename="libgazebo_ros2_control.so" name="gazebo_ros2_control">
      <parameters>$(find russ_moveit_node)/config/ros2_controllers.yaml</parameters>
      <robot_param_node>robot_state_publisher</robot_param_node>
    </plugin>
  </gazebo>

</robot>