<?xml version="1.0" encoding="utf-8"?>
<!-- This URDF was automatically created by SolidWorks to URDF Exporter! Originally created by Stephen Brawner (brawner@gmail.com) 
     Commit Version: 1.6.0-4-g7f85cfe  Build Version: 1.6.7995.38578
     For more information, please see http://wiki.ros.org/sw_urdf_exporter -->
<robot name="russ">
  <link name="table_base_link">
    <inertial>
      <origin xyz="8.3824E-08 0.2061 0.46328" rpy="0 0 0" />
      <mass value="309.14" />
      <inertia ixx="20.394" ixy="6.2669E-06" ixz="5.017E-06" iyy="26.052" iyz="-2.8893" izz="22.148" />
    </inertial>
    <visual>
      <origin xyz="0 0 0" rpy="0 0 0" />
      <geometry>
        <mesh filename="package://russ_description/meshes/man/base_link.STL" />
      </geometry>
      <material name="">
        <color rgba="0.89804 0.91765 0.92941 1" />
      </material>
    </visual>
    <collision>
      <origin xyz="0 0 0" rpy="0 0 0" />
      <geometry>
        <mesh filename="package://russ_description/meshes/man/base_link.STL" />
      </geometry>
    </collision>
  </link>
  <link name="world"/>
  <joint name="world_joint" type="fixed">
    <parent link="world"/>
    <child link="table_base_link"/>
    <origin rpy="0.0 0.0 0.0" xyz="0.0 0.0 0.0"/>
  </joint>
  <link name="bed_link">
    <inertial>
      <origin xyz="-1.3323E-15 -2.2204E-16 -0.086988" rpy="0 0 0" />
      <mass value="429.6" />
      <inertia ixx="25.702" ixy="-0.00012352" ixz="-1.3576E-13" iyy="178.76" iyz="-3.412E-14" izz="193.28" />
    </inertial>
    <visual>
      <origin xyz="0 0 0" rpy="0 0 0" />
      <geometry>
        <mesh filename="package://russ_description/meshes/man/bed_link.STL" />
      </geometry>
      <material name="">
        <color rgba="0.89804 0.91765 0.92941 1" />
      </material>
    </visual>
    <collision>
      <origin xyz="0 0 0" rpy="0 0 0" />
      <geometry>
        <mesh filename="package://russ_description/meshes/man/bed_link.STL" />
      </geometry>
    </collision>
  </link>
  <joint name="bed_joint" type="fixed">
    <origin xyz="-0.4 0.87 0.6" rpy="0 0 0" />
    <parent link="table_base_link" />
    <child link="bed_link" />
    <axis xyz="0 0 0" />
  </joint>
  <link name="man_link">
    <inertial>
      <origin xyz="-0.30355 0.067768 -0.10155" rpy="0 0 0" />
      <mass value="58.24" />
      <inertia ixx="0.70293" ixy="-0.0028572" ixz="-0.12719" iyy="8.0235" iyz="0.0098368" izz="8.4669" />
    </inertial>
    <visual>
      <origin xyz="0 0 0" rpy="0 0 0" />
      <geometry>
        <mesh filename="package://russ_description/meshes/man/man_link.STL" />
      </geometry>
      <material name="">
        <color rgba="1 1 1 1" />
      </material>
    </visual>
    <collision>
      <origin xyz="0 0 0" rpy="0 0 0" />
      <geometry>
        <mesh filename="package://russ_description/meshes/man/man_link.STL" />
      </geometry>
    </collision>
  </link>
  <joint name="man_joint" type="fixed">
    <origin xyz="0.466 -0.074751 0.19344" rpy="0 0 0" />
    <parent link="bed_link" />
    <child link="man_link" />
    <axis xyz="0 0 0" />
  </joint>
  <link name="camera_holder_link">
    <inertial>
      <origin xyz="0.440336125387075 -4.63518112781003E-15 0.698295733445473" rpy="0 0 0" />
      <mass value="10.7674813244167" />
      <inertia ixx="2.15585909806283" ixy="-4.98500136345296E-09" ixz="-1.23059570236083" iyy="2.84481281645542" iyz="2.87810900583756E-09" izz="0.760734918429647" />
    </inertial>
    <visual>
      <origin xyz="0 0 0" rpy="0 0 0" />
      <geometry>
        <mesh filename="package://russ_description/meshes/man/camera_holder_link.STL" />
      </geometry>
      <material name="">
        <color rgba="0.898039215686275 0.917647058823529 0.929411764705882 1" />
      </material>
    </visual>
    <collision>
      <origin xyz="0 0 0" rpy="0 0 0" />
      <geometry>
        <mesh filename="package://russ_description/meshes/man/camera_holder_link.STL" />
      </geometry>
    </collision>
  </link>
  <joint name="camera_holder_joint" type="fixed">
    <origin xyz="0 1.3665 1.4643" rpy="3.1416 0.5236 1.5708" />
    <parent link="table_base_link" />
    <child link="camera_holder_link" />
    <axis xyz="0 0 0" />
  </joint>
  <link name="kinect_link">
    <inertial>
      <origin xyz="0.0052461 0.00054533 -0.0069613" rpy="0 0 0" />
      <mass value="0.64645" />
      <inertia ixx="0.0028425" ixy="-2.566E-06" ixz="1.4774E-07" iyy="0.00026363" iyz="-3.4581E-08" izz="0.0029627" />
    </inertial>
    <visual>
      <origin xyz="0 0 0" rpy="0 0 0" />
      <geometry>
        <mesh filename="package://russ_description/meshes/man/camera_link.STL" />
      </geometry>
      <material name="">
        <color rgba="0.79216 0.81961 0.93333 1" />
      </material>
    </visual>
    <collision>
      <origin xyz="0 0 0" rpy="0 0 0" />
      <geometry>
        <mesh filename="package://russ_description/meshes/man/camera_link.STL" />
      </geometry>
    </collision>
  </link>
  <joint name="kinect_joint" type="fixed">
    <origin xyz="-0.0535 -0.00026386 0.011407" rpy="-1.8978 -1.5708 1.9025" />
    <parent link="camera_holder_link" />
    <child link="kinect_link" />
    <axis xyz="0 0 0" />
  </joint>
  <link name="base_link">
    <inertial>
      <origin xyz="0 0 0" rpy="0 0 0" />
      <mass value="4" />
      <inertia ixx="0" ixy="0" ixz="0" iyy="0" iyz="0" izz="0" />
    </inertial>
    <visual>
      <origin xyz="0 0 0" rpy="0 0 0" />
      <geometry>
        <mesh filename="package://russ_description/meshes/man/base.dae" />
      </geometry>
      <material name="">
        <color rgba="1 1 1 1" />
      </material>
    </visual>
    <collision>
      <origin xyz="0 0 0" rpy="0 0 0" />
      <geometry>
        <mesh filename="package://russ_description/meshes/man/arm_base_link.STL" />
      </geometry>
    </collision>
  </link>
  <joint name="base_joint" type="fixed">
    <origin xyz="0 0.37 0.7" rpy="0 0 0" />
    <parent link="table_base_link" />
    <child link="base_link" />
    <axis xyz="0 0 0" />
  </joint>
  <link name="shoulder_link">
    <inertial>
      <origin xyz="3.5038E-06 0.010909 0.00011678" rpy="0 0 0" />
      <mass value="3.7" />
      <inertia ixx="0.0039246" ixy="-4.6783E-08" ixz="4.0132E-08" iyy="0.0034476" iyz="-9.4718E-05" izz="0.0033425" />
    </inertial>
    <visual>
      <origin xyz="0 0 0" rpy="0 0 0" />
      <geometry>
        <mesh filename="package://russ_description/meshes/man/shoulder.dae" />
      </geometry>
      <material name="">
        <color rgba="1 1 1 1" />
      </material>
    </visual>
    <collision>
      <origin xyz="0 0 0" rpy="0 0 0" />
      <geometry>
        <mesh filename="package://russ_description/meshes/man/shoulder_link.STL" />
      </geometry>
    </collision>
  </link>
  <joint name="shoulder_joint" type="revolute">
    <origin xyz="0 0 0.1625" rpy="0 0 0" />
    <parent link="base_link" />
    <child link="shoulder_link" />
    <axis xyz="0 0 1" />
    <limit lower="-3.1416" upper="3.1416" effort="150" velocity="3.15" />
    <dynamics damping="0" friction="0" />
  </joint>
  <link name="upperarm_link">
    <inertial>
      <origin xyz="6.977E-06 0.00010671 0.2125" rpy="0 0 0" />
      <mass value="8.393" />
      <inertia ixx="0.14144" ixy="1.9188E-07" ixz="1.2835E-06" iyy="0.14028" iyz="-4.606E-07" izz="0.007421" />
    </inertial>
    <visual>
      <origin xyz="0 0 0" rpy="0 0 0" />
      <geometry>
        <mesh filename="package://russ_description/meshes/man/upperarm.dae" />
      </geometry>
      <material name="">
        <color rgba="1 1 1 1" />
      </material>
    </visual>
    <collision>
      <origin xyz="0 0 0" rpy="0 0 0" />
      <geometry>
        <mesh filename="package://russ_description/meshes/man/upperarm_link.STL" />
      </geometry>
    </collision>
  </link>
  <joint name="upperarm_joint" type="revolute">
    <origin xyz="0 0.1378 0" rpy="0 0 0" />
    <parent link="shoulder_link" />
    <child link="upperarm_link" />
    <axis xyz="0 1 0" />
    <!-- <limit lower="-3.1416" upper="3.1416" effort="150" velocity="3.15" /> -->
    <!-- 1.4137rad = 81° -->
    <limit lower="-1.4137" upper="1.4137" effort="150" velocity="3.15" />
    <dynamics damping="0" friction="0" />
  </joint>
  <link name="forearm_link">
    <inertial>
      <origin xyz="-2.2956E-05 0.010608 0.14792" rpy="0 0 0" />
      <mass value="2.275" />
      <inertia ixx="0.053639" ixy="1.0574E-05" ixz="-9.1444E-06" iyy="0.053127" iyz="0.0035172" izz="0.0026829" />
    </inertial>
    <visual>
      <origin xyz="0 0 0" rpy="0 0 0" />
      <geometry>
        <mesh filename="package://russ_description/meshes/man/forearm.dae" />
      </geometry>
      <material name="">
        <color rgba="1 1 1 1" />
      </material>
    </visual>
    <collision>
      <origin xyz="0 0 0" rpy="0 0 0" />
      <geometry>
        <mesh filename="package://russ_description/meshes/man/forearm_link.STL" />
      </geometry>
    </collision>
  </link>
  <joint name="forearm_joint" type="revolute">
    <origin xyz="0 -0.1312 0.425" rpy="0 0 0" />
    <parent link="upperarm_link" />
    <child link="forearm_link" />
    <axis xyz="0 1 0" />
    <limit lower="-3.1416" upper="3.1416" effort="150" velocity="3.15" />
    <dynamics damping="0" friction="0" />
  </joint>
  <link name="wrist1_link">
    <inertial>
      <origin xyz="-8.3494E-06 0.10839 -0.002548" rpy="0 0 0" />
      <mass value="1.219" />
      <inertia ixx="0.0010919" ixy="2.8181E-07" ixz="-1.116E-07" iyy="0.00068611" iyz="2.5893E-05" izz="0.00088473" />
    </inertial>
    <visual>
      <origin xyz="0 0 0" rpy="0 0 0" />
      <geometry>
        <mesh filename="package://russ_description/meshes/man/wrist1.dae" />
      </geometry>
      <material name="">
        <color rgba="1 1 1 1" />
      </material>
    </visual>
    <collision>
      <origin xyz="0 0 0" rpy="0 0 0" />
      <geometry>
        <mesh filename="package://russ_description/meshes/man/wrist1_link.STL" />
      </geometry>
    </collision>
  </link>
  <joint name="wrist1_joint" type="revolute">
    <origin xyz="0 0 0.39225" rpy="0 0 0" />
    <parent link="forearm_link" />
    <child link="wrist1_link" />
    <axis xyz="0 1 0" />
    <limit lower="-3.1416" upper="3.1416" effort="28" velocity="3.2" />
    <dynamics damping="0" friction="0" />
  </joint>
  <link name="wrist2_link">
    <inertial>
      <origin xyz="8.9598E-06 -0.00311 0.092148" rpy="0 0 0" />
      <mass value="1.219" />
      <inertia ixx="0.00069812" ixy="1.1122E-07" ixz="-2.3236E-07" iyy="0.00049175" iyz="7.5563E-06" izz="0.00060119" />
    </inertial>
    <visual>
      <origin xyz="0 0 0" rpy="0 0 0" />
      <geometry>
        <mesh filename="package://russ_description/meshes/man/wrist2.dae" />
      </geometry>
      <material name="">
        <color rgba="1 1 1 1" />
      </material>
    </visual>
    <collision>
      <origin xyz="0 0 0" rpy="0 0 0" />
      <geometry>
        <mesh filename="package://russ_description/meshes/man/wrist2_link.STL" />
      </geometry>
    </collision>
  </link>
  <joint name="wrist2_joint" type="revolute">
    <origin xyz="0 0.1267 0" rpy="0 0 0" />
    <parent link="wrist1_link" />
    <child link="wrist2_link" />
    <axis xyz="0 0 1" />
    <limit lower="-3.1416" upper="3.1416" effort="28" velocity="3.2" />
    <dynamics damping="0" friction="0" />
  </joint>
  <link name="wrist3_link">
    <inertial>
      <origin xyz="-2.1553E-09 0.075061 -1.5939E-05" rpy="0 0 0" />
      <mass value="0.1879" />
      <inertia ixx="0.00012784" ixy="8.6493E-12" ixz="-2.7362E-09" iyy="0.00016475" iyz="-1.6102E-07" izz="0.00012855" />
    </inertial>
    <visual>
      <origin xyz="0 0 0" rpy="0 0 0" />
      <geometry>
        <mesh filename="package://russ_description/meshes/man/wrist3.dae" />
      </geometry>
      <material name="">
        <color rgba="1 1 1 1" />
      </material>
    </visual>
    <collision>
      <origin xyz="0 0 0" rpy="0 0 0" />
      <geometry>
        <mesh filename="package://russ_description/meshes/man/wrist3_link.STL" />
      </geometry>
    </collision>
  </link>
  <joint name="wrist3_joint" type="revolute">
    <origin xyz="0 0 0.0997" rpy="0 0 0" />
    <parent link="wrist2_link" />
    <child link="wrist3_link" />
    <axis xyz="0 1 0" />
    <limit lower="-3.1416" upper="3.1416" effort="28" velocity="3.2" />
    <dynamics damping="0" friction="0" />
  </joint>
  <link name="upperprobe_link">
    <inertial>
      <origin xyz="-6.63458796418825E-05 0.0870563931078425 6.63349804452817E-05" rpy="0 0 0" />
      <mass value="0.29224119341871" />
      <inertia ixx="0.000539961437048322" ixy="8.57640660432055E-07" ixz="-1.68597761634735E-05" iyy="0.000122878958889507" iyz="-8.56331344497876E-07" izz="0.000539963118368424" />
    </inertial>
    <visual>
      <origin xyz="0 0 0" rpy="0 0 0" />
      <geometry>
        <mesh filename="package://russ_description/meshes/man/upperprobe_link.STL" />
      </geometry>
      <material name="">
        <color rgba="0.792156862745098 0.819607843137255 0.933333333333333 1" />
      </material>
    </visual>
    <collision>
      <origin xyz="0 0 0" rpy="0 0 0" />
      <geometry>
        <mesh filename="package://russ_description/meshes/man/upperprobe_link.STL" />
      </geometry>
    </collision>
  </link>
  <joint name="upperprobe_joint" type="fixed">
    <origin xyz="0 0.1086 0" rpy="0 0 0" />
    <parent link="wrist3_link" />
    <child link="upperprobe_link" />
    <axis xyz="0 0 0" />
  </joint>
  <link name="probe_link">
    <inertial>
      <origin xyz="-0.000325357010050917 -0.00796680505131175 0.000325397027811647" rpy="0 0 0" />
      <mass value="0.0275873695177772" />
      <inertia ixx="6.56286772751349E-06" ixy="-5.48238728667042E-11" ixz="-2.04472096416803E-06" iyy="1.25436023819217E-05" iyz="-5.18677191691285E-11" izz="6.56290712583165E-06" />
    </inertial>
    <visual>
      <origin xyz="0 0 0" rpy="0 0 0" />
      <geometry>
        <mesh filename="package://russ_description/meshes/man/probe_link.STL" />
      </geometry>
      <material name="">
        <color rgba="0.792156862745098 0.819607843137255 0.933333333333333 1" />
      </material>
    </visual>
    <collision>
      <origin xyz="0 0 0" rpy="0 0 0" />
      <geometry>
        <mesh filename="package://russ_description/meshes/man/probe_link.STL" />
      </geometry>
    </collision>
  </link>
  <joint name="probe_joint" type="fixed">
    <origin xyz="0 0.16 0" rpy="0 0 0" />
    <parent link="upperprobe_link" />
    <child link="probe_link" />
    <axis xyz="0 0 0" />
  </joint>

  <ros2_control name="GazeboSystem" type="system">
    <hardware>
      <plugin>gazebo_ros2_control/GazeboSystem</plugin>
    </hardware>
    <joint name="shoulder_joint">
      <command_interface name="position">
        <param name="min">-1</param>
        <param name="max">1</param>
      </command_interface>
      <state_interface name="position">
        <param name="initial_value">0.0</param>
      </state_interface>
      <state_interface name="velocity"/>
    </joint>
    <joint name="upperarm_joint">
      <command_interface name="position">
        <param name="min">-1</param>
        <param name="max">1</param>
      </command_interface>
      <state_interface name="position">
        <param name="initial_value">0.0</param>
      </state_interface>
      <state_interface name="velocity"/>
    </joint>
    <joint name="forearm_joint">
      <command_interface name="position">
        <param name="min">-1</param>
        <param name="max">1</param>
      </command_interface>
      <state_interface name="position">
        <param name="initial_value">0.0</param>
      </state_interface>
      <state_interface name="velocity"/>
    </joint>
    <joint name="wrist1_joint">
      <command_interface name="position">
        <param name="min">-1</param>
        <param name="max">1</param>
      </command_interface>
      <state_interface name="position">
        <param name="initial_value">0.0</param>
      </state_interface>
      <state_interface name="velocity"/>
    </joint>
    <joint name="wrist2_joint">
      <command_interface name="position">
        <param name="min">-1</param>
        <param name="max">1</param>
      </command_interface>
      <state_interface name="position">
        <param name="initial_value">0.0</param>
      </state_interface>
      <state_interface name="velocity"/>
    </joint>
    <joint name="wrist3_joint">
      <command_interface name="position">
        <param name="min">-1</param>
        <param name="max">1</param>
      </command_interface>
      <state_interface name="position">
        <param name="initial_value">0.0</param>
      </state_interface>
      <state_interface name="velocity"/>
    </joint>
  </ros2_control>

  <gazebo reference="kinect_link">
    <sensor type="depth" name="camera">
      <!-- Set always_on only sensor, not on plugin -->
      <always_on>1</always_on>

      <!-- Set update_rate only sensor, not on plugin -->
      <update_rate>20.0</update_rate>

      <camera name="kinect">
        <horizontal_fov>1.05</horizontal_fov>
        <image>
          <format>R8G8B8</format>
          <width>640</width>
          <height>480</height>
        </image>
        <clip>
          <near>0.05</near>
          <far>3.0</far>
        </clip>
        <distortion>
          <k1>0.0</k1>
          <k2>0.0</k2>
          <k3>0.0</k3>
          <p1>0.0</p1>
          <p2>0.0</p2>
          <center>0.0 0.0</center>
        </distortion>
      </camera>
      <plugin name="kinect_camera_controller" filename="libgazebo_ros_camera.so">
        <!-- Change namespace, camera name and topics so -
                 * Raw images are published to: /custom_ns/custom_camera/custom_image
                 * Depth images are published to: /custom_ns/custom_camera/custom_image_depth
                 * Raw image camera info is published to: /custom_ns/custom_camera/custom_info_raw
                 * Depth image camera info is published to: /custom_ns/custom_camera/custom_info_depth
                 * Point cloud is published to: /custom_ns/custom_camera/custom_points
            -->
        <ros>
          <namespace>custom_ns</namespace>
          <remapping>custom_camera/image_raw:=custom_camera/custom_image</remapping>
          <remapping>custom_camera/image_depth:=custom_camera/custom_image_depth</remapping>
          <remapping>custom_camera/camera_info:=custom_camera/custom_info_raw</remapping>
          <remapping>custom_camera/camera_info_depth:=custom_camera/custom_info_depth</remapping>
          <remapping>custom_camera/points:=custom_camera/custom_points</remapping>
        </ros>

        <!-- Set camera name. If empty, defaults to sensor name (i.e. "sensor_name") -->
        <camera_name>custom_camera</camera_name>

        <!-- Set TF frame name. If empty, defaults to link name (i.e. "link_name") -->
        <frame_name>kinect_link</frame_name>
        <!-- <frame_name>base_link</frame_name> -->
        <!-- <frame_name>world</frame_name> -->

        <hack_baseline>0.07</hack_baseline>

        <!-- No need to repeat distortion parameters or to set autoDistortion -->

        <min_depth>0.001</min_depth>
        <max_depth>300.0</max_depth>
      </plugin>
    </sensor>
  </gazebo>

  <gazebo>
    <plugin filename="libgazebo_ros2_control.so" name="gazebo_ros2_control">
      <parameters>$(find russ_moveit_node)/config/ros2_controllers.yaml</parameters>
      <robot_param_node>robot_state_publisher</robot_param_node>
    </plugin>
  </gazebo>

</robot>