<?xml version="1.0"?>

<robot name="ur5e">
  <link name="base_link">
    <visual>
      <geometry>
        <mesh filename="package://ur_description/meshes/ur5e/visual/base.dae"/>
      </geometry>
      <material name="LightGrey">
        <color rgba="0.7 0.7 0.7 1.0"/>
      </material>
    </visual>
    <collision>
      <geometry>
        <mesh filename="package://ur_description/meshes/ur5e/collision/base.stl"/>
      </geometry>
    </collision>
    <inertial>
      <mass value="4.0"/>
      <origin rpy="0 0 0" xyz="0.0 0.0 0.0"/>
      <inertia ixx="0.00443333156" ixy="0.0" ixz="0.0" iyy="0.00443333156" iyz="0.0" izz="0.0072"/>
    </inertial>
  </link>
  <joint name="shoulder_pan_joint" type="revolute">
    <parent link="base_link"/>
    <child link="shoulder_link"/>
    <origin rpy="0.0 0.0 0.0" xyz="0.0 0.0 0.089159"/>
    <axis xyz="0 0 1"/>
    <limit effort="150.0" lower="-3.14159265" upper="3.14159265" velocity="3.15"/>
    <dynamics damping="0.0" friction="0.0"/>
  </joint>
  <link name="shoulder_link">
    <visual>
      <geometry>
        <mesh filename="package://ur_description/meshes/ur5e/visual/shoulder.dae"/>
      </geometry>
      <material name="LightGrey">
        <color rgba="0.7 0.7 0.7 1.0"/>
      </material>
    </visual>
    <collision>
      <geometry>
        <mesh filename="package://ur_description/meshes/ur5e/collision/shoulder.stl"/>
      </geometry>
    </collision>
    <inertial>
      <mass value="3.7"/>
      <origin rpy="0 0 0" xyz="0.0 0.0 0.0"/>
      <inertia ixx="0.010267495893" ixy="0.0" ixz="0.0" iyy="0.010267495893" iyz="0.0" izz="0.00666"/>
    </inertial>
  </link>
  <joint name="shoulder_lift_joint" type="revolute">
    <parent link="shoulder_link"/>
    <child link="upper_arm_link"/>
    <origin rpy="0.0 1.570796325 0.0" xyz="0.0 0.13585 0.0"/>
    <axis xyz="0 1 0"/>
    <limit effort="150.0" lower="-3.14159265" upper="3.14159265" velocity="3.15"/>
    <dynamics damping="0.0" friction="0.0"/>
  </joint>
  <link name="upper_arm_link">
    <visual>
      <geometry>
        <mesh filename="package://ur_description/meshes/ur5e/visual/upperarm.dae"/>
      </geometry>
      <material name="LightGrey">
        <color rgba="0.7 0.7 0.7 1.0"/>
      </material>
    </visual>
    <collision>
      <geometry>
        <mesh filename="package://ur_description/meshes/ur5e/collision/upperarm.stl"/>
      </geometry>
    </collision>
    <inertial>
      <mass value="8.393"/>
      <origin rpy="0 0 0" xyz="0.0 0.0 0.28"/>
      <inertia ixx="0.22689067591" ixy="0.0" ixz="0.0" iyy="0.22689067591" iyz="0.0" izz="0.0151074"/>
    </inertial>
  </link>
  <joint name="elbow_joint" type="revolute">
    <parent link="upper_arm_link"/>
    <child link="forearm_link"/>
    <origin rpy="0.0 0.0 0.0" xyz="0.0 -0.1197 0.425"/>
    <axis xyz="0 1 0"/>
    <limit effort="150.0" lower="-3.14159265" upper="3.14159265" velocity="3.15"/>
    <dynamics damping="0.0" friction="0.0"/>
  </joint>
  <link name="forearm_link">
    <visual>
      <geometry>
        <mesh filename="package://ur_description/meshes/ur5e/visual/forearm.dae"/>
      </geometry>
      <material name="LightGrey">
        <color rgba="0.7 0.7 0.7 1.0"/>
      </material>
    </visual>
    <collision>
      <geometry>
        <mesh filename="package://ur_description/meshes/ur5e/collision/forearm.stl"/>
      </geometry>
    </collision>
    <inertial>
      <mass value="2.275"/>
      <origin rpy="0 0 0" xyz="0.0 0.0 0.25"/>
      <inertia ixx="0.049443313556" ixy="0.0" ixz="0.0" iyy="0.049443313556" iyz="0.0" izz="0.004095"/>
    </inertial>
  </link>
  <joint name="wrist_1_joint" type="revolute">
    <parent link="forearm_link"/>
    <child link="wrist_1_link"/>
    <origin rpy="0.0 -1.570796325 0.0" xyz="0.0 0.0 0.39225"/>
    <axis xyz="0 1 0"/>
    <limit effort="28.0" lower="-3.14159265" upper="3.14159265" velocity="3.2"/>
    <dynamics damping="0.0" friction="0.0"/>
  </joint>
  <link name="wrist_1_link">
    <visual>
      <geometry>
        <mesh filename="package://ur_description/meshes/ur5e/visual/wrist1.dae"/>
      </geometry>
      <material name="LightGrey">
        <color rgba="0.7 0.7 0.7 1.0"/>
      </material>
    </visual>
    <collision>
      <geometry>
        <mesh filename="package://ur_description/meshes/ur5e/collision/wrist1.stl"/>
      </geometry>
    </collision>
    <inertial>
      <mass value="1.219"/>
      <origin rpy="0 0 0" xyz="0.0 0.0 0.0"/>
      <inertia ixx="0.111172755531" ixy="0.0" ixz="0.0" iyy="0.111172755531" iyz="0.0" izz="0.21942"/>
    </inertial>
  </link>
  <joint name="wrist_2_joint" type="revolute">
    <parent link="wrist_1_link"/>
    <child link="wrist_2_link"/>
    <origin rpy="0.0 0.0 0.0" xyz="0.0 0.093 0.0"/>
    <axis xyz="0 0 1"/>
    <limit effort="28.0" lower="-3.14159265" upper="3.14159265" velocity="3.2"/>
    <dynamics damping="0.0" friction="0.0"/>
  </joint>
  <link name="wrist_2_link">
    <visual>
      <geometry>
        <mesh filename="package://ur_description/meshes/ur5e/visual/wrist2.dae"/>
      </geometry>
      <material name="LightGrey">
        <color rgba="0.7 0.7 0.7 1.0"/>
      </material>
    </visual>
    <collision>
      <geometry>
        <mesh filename="package://ur_description/meshes/ur5e/collision/wrist2.stl"/>
      </geometry>
    </collision>
    <inertial>
      <mass value="1.219"/>
      <origin rpy="0 0 0" xyz="0.0 0.0 0.0"/>
      <inertia ixx="0.111172755531" ixy="0.0" ixz="0.0" iyy="0.111172755531" iyz="0.0" izz="0.21942"/>
    </inertial>
  </link>
  <joint name="wrist_3_joint" type="revolute">
    <parent link="wrist_2_link"/>
    <child link="wrist_3_link"/>
    <origin rpy="0.0 0.0 0.0" xyz="0.0 0.0 0.09465"/>
    <axis xyz="0 1 0"/>
    <limit effort="28.0" lower="-3.14159265" upper="3.14159265" velocity="3.2"/>
    <dynamics damping="0.0" friction="0.0"/>
  </joint>
  <link name="wrist_3_link">
    <visual>
      <geometry>
        <mesh filename="package://ur_description/meshes/ur5e/visual/wrist3.dae"/>
      </geometry>
      <material name="LightGrey">
        <color rgba="0.7 0.7 0.7 1.0"/>
      </material>
    </visual>
    <collision>
      <geometry>
        <mesh filename="package://ur_description/meshes/ur5e/collision/wrist3.stl"/>
      </geometry>
    </collision>
    <inertial>
      <mass value="0.1879"/>
      <origin rpy="0 0 0" xyz="0.0 0.0 0.0"/>
      <inertia ixx="0.0171364731454" ixy="0.0" ixz="0.0" iyy="0.0171364731454" iyz="0.0" izz="0.033822"/>
    </inertial>
  </link>
  <joint name="ee_fixed_joint" type="fixed">
    <parent link="wrist_3_link"/>
    <child link="ee_link"/>
    <origin rpy="0.0 0.0 1.570796325" xyz="0.0 0.0823 0.0"/>
    <!-- <origin rpy="0.0 0.0 0.0" xyz="0.0 0.0823 0.0"/> -->
  </joint>
  <link name="ee_link">
    <collision>
      <geometry>
        <box size="0.01 0.01 0.01"/>
      </geometry>
      <origin rpy="0 0 0" xyz="-0.01 0 0"/>
    </collision>
  </link>
  <link name="world"/>
  <joint name="world_joint" type="fixed">
    <parent link="world"/>
    <child link="base_link"/>
    <origin rpy="0.0 0.0 0.0" xyz="0.0 0.0 0.0"/>
  </joint>

  <link name="kinect_link">
    <origin xyz="0 0 0" rpy="0 0 0"/>
    <visual>
      <origin xyz="0 0 0" rpy="0 0 1.5708"/>
      <geometry>
        <mesh filename="package://ur_description/meshes/kinect/kinect.dae" />
      </geometry>
    </visual>
    <collision>
      <geometry>
        <box size="0.07 0.3 0.09"/>
      </geometry>
    </collision>
  </link>

  <joint name="kinect_joint" type="fixed">
    <origin xyz="0 0 0" rpy="0 0 0"/>
    <!-- <parent link="wrist_3_link"/> -->
    <parent link="ee_link"/>
    <child link="kinect_link"/>
  </joint>

  <ros2_control name="GazeboSystem" type="system">
    <hardware>
      <plugin>gazebo_ros2_control/GazeboSystem</plugin>
    </hardware>
    <joint name="shoulder_pan_joint">
      <command_interface name="position">
        <param name="min">-1</param>
        <param name="max">1</param>
      </command_interface>
      <state_interface name="position">
        <param name="initial_value">0.0</param>
      </state_interface>
      <state_interface name="velocity"/>
    </joint>
    <joint name="shoulder_lift_joint">
      <command_interface name="position">
        <param name="min">-1</param>
        <param name="max">1</param>
      </command_interface>
      <state_interface name="position">
        <param name="initial_value">0.0</param>
      </state_interface>
      <state_interface name="velocity"/>
    </joint>
    <joint name="elbow_joint">
      <command_interface name="position">
        <param name="min">-1</param>
        <param name="max">1</param>
      </command_interface>
      <state_interface name="position">
        <param name="initial_value">0.0</param>
      </state_interface>
      <state_interface name="velocity"/>
    </joint>
    <joint name="wrist_1_joint">
      <command_interface name="position">
        <param name="min">-1</param>
        <param name="max">1</param>
      </command_interface>
      <state_interface name="position">
        <param name="initial_value">0.0</param>
      </state_interface>
      <state_interface name="velocity"/>
    </joint>
    <joint name="wrist_2_joint">
      <command_interface name="position">
        <param name="min">-1</param>
        <param name="max">1</param>
      </command_interface>
      <state_interface name="position">
        <param name="initial_value">0.0</param>
      </state_interface>
      <state_interface name="velocity"/>
    </joint>
    <joint name="wrist_3_joint">
      <command_interface name="position">
        <param name="min">-1</param>
        <param name="max">1</param>
      </command_interface>
      <state_interface name="position">
        <param name="initial_value">0.0</param>
      </state_interface>
      <state_interface name="velocity"/>
    </joint>
  </ros2_control>

  <gazebo reference="kinect_link">
    <sensor type="depth" name="camera">
      <!-- Set always_on only sensor, not on plugin -->
      <always_on>1</always_on>

      <!-- Set update_rate only sensor, not on plugin -->
      <update_rate>20.0</update_rate>

      <camera name="kinect">
        <horizontal_fov>1.05</horizontal_fov>
        <image>
          <format>R8G8B8</format>
          <width>640</width>
          <height>480</height>
        </image>
        <clip>
          <near>0.05</near>
          <far>8.0</far>
        </clip>
        <distortion>
          <k1>0.0</k1>
          <k2>0.0</k2>
          <k3>0.0</k3>
          <p1>0.0</p1>
          <p2>0.0</p2>
          <center>0.0 0.0</center>
        </distortion>
      </camera>
      <plugin name="kinect_camera_controller" filename="libgazebo_ros_camera.so">
        <!-- Change namespace, camera name and topics so -
                 * Raw images are published to: /custom_ns/custom_camera/custom_image
                 * Depth images are published to: /custom_ns/custom_camera/custom_image_depth
                 * Raw image camera info is published to: /custom_ns/custom_camera/custom_info_raw
                 * Depth image camera info is published to: /custom_ns/custom_camera/custom_info_depth
                 * Point cloud is published to: /custom_ns/custom_camera/custom_points
            -->
        <ros>
          <namespace>custom_ns</namespace>
          <remapping>custom_camera/image_raw:=custom_camera/custom_image</remapping>
          <remapping>custom_camera/image_depth:=custom_camera/custom_image_depth</remapping>
          <remapping>custom_camera/camera_info:=custom_camera/custom_info_raw</remapping>
          <remapping>custom_camera/camera_info_depth:=custom_camera/custom_info_depth</remapping>
          <remapping>custom_camera/points:=custom_camera/custom_points</remapping>
        </ros>

        <!-- Set camera name. If empty, defaults to sensor name (i.e. "sensor_name") -->
        <camera_name>custom_camera</camera_name>

        <!-- Set TF frame name. If empty, defaults to link name (i.e. "link_name") -->
        <frame_name>kinect_link</frame_name>
        <!-- <frame_name>base_link</frame_name> -->

        <hack_baseline>0.07</hack_baseline>

        <!-- No need to repeat distortion parameters or to set autoDistortion -->

        <min_depth>0.001</min_depth>
        <max_depth>300.0</max_depth>
      </plugin>
    </sensor>
  </gazebo>

  <gazebo>
    <plugin filename="libgazebo_ros2_control.so" name="gazebo_ros2_control">
      <parameters>$(find ur)/config/ros2_controllers.yaml</parameters>
      <robot_param_node>robot_state_publisher</robot_param_node>
    </plugin>
  </gazebo>
</robot>

